<?xml version="1.0" ?>
<!-- =================================================================================== -->
<!-- |    This document was autogenerated by xacro from akira_with_arm.xacro           | -->
<!-- |    EDITING THIS FILE BY HAND IS NOT RECOMMENDED                                 | -->
<!-- =================================================================================== -->
<robot name="akira" xmlns:xacro="http://ros.org/wiki/xacro">
  <!-- Define a number of dimensions using properties -->
  <!-- Include all component files -->
  <material name="Black">
    <color rgba="0.2 0.2 0.2 1.0"/>
  </material>
  <material name="TransparentBlack">
    <color rgba="0.2 0.2 0.2 0.8"/>
  </material>
  <material name="Orange">
    <color rgba="1.0 0.55 0.0 1.0"/>
  </material>
  <material name="Grey">
    <color rgba="0.7 0.7 0.7 1.0"/>
  </material>
  <material name="DarkGrey">
    <color rgba="0.3 0.3 0.3 1.0"/>
  </material>
  <material name="Red">
    <color rgba="0.8 0.0 0.0 1.0"/>
  </material>
  <material name="White">
    <color rgba="1.0 1.0 1.0 1.0"/>
  </material>
  <material name="OffWhite">
    <color rgba="0.8 0.8 0.8 1.0"/>
  </material>
  <material name="Blue">
    <color rgba="0.0 0.0 0.8 1.0"/>
  </material>
  <material name="Green">
    <color rgba="0.0 0.8 0.0 1.0"/>
  </material>
  <material name="TransparentGreen">
    <color rgba="0.0 0.8 0.0 0.5"/>
  </material>
  <link name="base_footprint">
    <visual>
      <origin rpy="0 0 0" xyz="0 0 0"/>
      <geometry>
        <box size="0.05 0.05 0.001"/>
      </geometry>
      <material name="TransparentGreen"/>
    </visual>
  </link>
  <joint name="base_joint" type="fixed">
    <origin rpy="0 0 0" xyz="0 0 0.15"/>
    <parent link="base_footprint"/>
    <child link="base_link"/>
  </joint>
  <!-- Add the base and wheels -->
  <link name="base_link">
    <!-- kokoha atode mesh ninarukamo -->
    <visual>
      <origin rpy="0 0 0" xyz="0 0 0"/>
      <geometry>
        <mesh filename="package://akira_description/meshes/akira_vehicle.stl" scale="1.0 1.0 1.0"/>
      </geometry>
      <material name="Black"/>
    </visual>
    <collision>
      <origin rpy="0 0 0" xyz="0 0 0"/>
      <geometry>
        <!-- OK? -->
        <cylinder length="0.3" radius="0.25"/>
      </geometry>
    </collision>
  </link>
  <!-- Attach the torso -->
  <joint name="base_torso_joint" type="fixed">
    <origin rpy="0 0 0" xyz="0.0 0.0 0.55"/>
    <parent link="base_link"/>
    <child link="torso_link"/>
  </joint>
  <link name="torso_link">
    <visual>
      <origin rpy="0 0 0" xyz="0 0 0"/>
      <geometry>
        <mesh filename="package://akira_description/meshes/akira_torso.stl" scale="1.0 1.0 1.0"/>
      </geometry>
      <material name="Grey"/>
    </visual>
    <collision>
      <origin rpy="0 0 0" xyz="0 0 0"/>
      <geometry>
        <box size="0.29 0.46 0.77"/>
      </geometry>
    </collision>
  </link>
  <!-- Attach the right arm -->
  <link name="right_arm_base_link"/>
  <joint name="right_arm_base_joint" type="fixed">
    <origin rpy="0 0 0" xyz="0.1 -0.2 0.2"/>
    <parent link="torso_link"/>
    <child link="right_arm_base_link"/>
  </joint>
  <joint name="right_arm_shoulder_lift_R_joint" type="revolute">
    <origin rpy="-1.570795 1.570795 0" xyz="0 0 0"/>
    <axis xyz="0 0 1"/>
    <limit effort="1.0" lower="-3.14" upper="3.14" velocity="1.571"/>
    <parent link="right_arm_base_link"/>
    <child link="right_arm_shoulder_lift_R_link"/>
  </joint>
  <link name="right_arm_shoulder_lift_R_link">
    <inertial>
      <mass value="0.00001"/>
      <origin xyz="0 0 0"/>
      <inertia ixx="1.0" ixy="0.0" ixz="0.0" iyy="1.0" iyz="0.0" izz="1.0"/>
    </inertial>
    <visual>
      <origin rpy="0 0 0" xyz="0 0 0"/>
      <geometry>
        <mesh filename="package://akira_description/meshes/RS405CB.stl" scale="0.001 0.001 0.001"/>
      </geometry>
      <material name="Black"/>
    </visual>
    <collision>
      <origin rpy="0 0 0" xyz="-0.01 0.0 -0.0225"/>
      <geometry>
        <box size="0.043 0.033 0.045"/>
      </geometry>
    </collision>
  </link>
  <joint name="right_arm_shoulder_lift_L_joint" type="revolute">
    <origin rpy="1.570795 1.570795 0" xyz="0 -0.09 0"/>
    <axis xyz="0 0 1"/>
    <limit effort="1.0" lower="-3.14" upper="3.14" velocity="1.571"/>
    <parent link="right_arm_base_link"/>
    <child link="right_arm_shoulder_lift_L_link"/>
  </joint>
  <link name="right_arm_shoulder_lift_L_link">
    <inertial>
      <mass value="0.00001"/>
      <origin xyz="0 0 0"/>
      <inertia ixx="1.0" ixy="0.0" ixz="0.0" iyy="1.0" iyz="0.0" izz="1.0"/>
    </inertial>
    <visual>
      <origin rpy="0 0 0" xyz="0 0 0"/>
      <geometry>
        <mesh filename="package://akira_description/meshes/RS405CB.stl" scale="0.001 0.001 0.001"/>
      </geometry>
      <material name="Black"/>
    </visual>
    <collision>
      <origin rpy="0 0 0" xyz="-0.01 0.0 -0.0225"/>
      <geometry>
        <box size="0.043 0.033 0.045"/>
      </geometry>
    </collision>
  </link>
  <joint name="right_arm_shoulder_roll_joint" type="revolute">
    <origin rpy="1.570795 0 3.14159" xyz="0 0.0215 0.06"/>
    <axis xyz="0 0 1"/>
    <limit effort="1.0" lower="-3.14" upper="3.14" velocity="1.571"/>
    <parent link="right_arm_shoulder_lift_L_link"/>
    <child link="right_arm_shoulder_roll_link"/>
  </joint>
  <link name="right_arm_shoulder_roll_link">
    <inertial>
      <mass value="0.00001"/>
      <origin xyz="0 0 0"/>
      <inertia ixx="1.0" ixy="0.0" ixz="0.0" iyy="1.0" iyz="0.0" izz="1.0"/>
    </inertial>
    <visual>
      <origin rpy="0 0 0" xyz="0 0 0"/>
      <geometry>
        <mesh filename="package://akira_description/meshes/RS405CB.stl" scale="0.001 0.001 0.001"/>
      </geometry>
      <material name="Black"/>
    </visual>
    <collision>
      <origin rpy="0 0 0" xyz="-0.01 0.0 -0.0225"/>
      <geometry>
        <box size="0.043 0.033 0.045"/>
      </geometry>
    </collision>
  </link>
  <joint name="right_arm_shoulder_pan_joint" type="revolute">
    <origin rpy="3.14159 -1.570795 0" xyz="-0.052 0 -0.0215"/>
    <axis xyz="0 0 1"/>
    <limit effort="1.0" lower="-2.7" upper="2.7" velocity="1.571"/>
    <parent link="right_arm_shoulder_roll_link"/>
    <child link="right_arm_shoulder_pan_link"/>
  </joint>
  <link name="right_arm_shoulder_pan_link">
    <inertial>
      <mass value="0.00001"/>
      <origin xyz="0 0 0"/>
      <inertia ixx="1.0" ixy="0.0" ixz="0.0" iyy="1.0" iyz="0.0" izz="1.0"/>
    </inertial>
    <visual>
      <origin rpy="0 0 0" xyz="0 0 0"/>
      <geometry>
        <mesh filename="package://akira_description/meshes/RS405CB.stl" scale="0.001 0.001 0.001"/>
      </geometry>
      <material name="Black"/>
    </visual>
    <collision>
      <origin rpy="0 0 0" xyz="-0.01 0.0 -0.0225"/>
      <geometry>
        <box size="0.043 0.033 0.045"/>
      </geometry>
    </collision>
  </link>
  <joint name="right_arm_elbow_flex_joint" type="revolute">
    <origin rpy="-1.570795 0 0" xyz="0 0.0225 -0.0865"/>
    <axis xyz="0 0 1"/>
    <limit effort="1.0" lower="-2.7" upper="2.7" velocity="1.571"/>
    <parent link="right_arm_shoulder_pan_link"/>
    <child link="right_arm_elbow_flex_link"/>
  </joint>
  <link name="right_arm_elbow_flex_link">
    <inertial>
      <mass value="0.00001"/>
      <origin xyz="0 0 0"/>
      <inertia ixx="1.0" ixy="0.0" ixz="0.0" iyy="1.0" iyz="0.0" izz="1.0"/>
    </inertial>
    <visual>
      <origin rpy="0 0 0" xyz="0 0 0"/>
      <geometry>
        <mesh filename="package://akira_description/meshes/RS405CB.stl" scale="0.001 0.001 0.001"/>
      </geometry>
      <material name="Black"/>
    </visual>
    <collision>
      <origin rpy="0 0 0" xyz="-0.01 0.0 -0.0225"/>
      <geometry>
        <box size="0.043 0.033 0.045"/>
      </geometry>
    </collision>
  </link>
  <joint name="right_arm_forearm_flex_joint" type="revolute">
    <origin rpy="1.570795 0 0" xyz="0 0.032 -0.0225"/>
    <axis xyz="0 0 1"/>
    <limit effort="1.0" lower="-2.7" upper="2.7" velocity="1.571"/>
    <parent link="right_arm_elbow_flex_link"/>
    <child link="right_arm_forearm_flex_link"/>
  </joint>
  <link name="right_arm_forearm_flex_link">
    <inertial>
      <mass value="0.00001"/>
      <origin xyz="0 0 0"/>
      <inertia ixx="1.0" ixy="0.0" ixz="0.0" iyy="1.0" iyz="0.0" izz="1.0"/>
    </inertial>
    <visual>
      <origin rpy="0 0 0" xyz="0 0 0"/>
      <geometry>
        <mesh filename="package://akira_description/meshes/RS405CB.stl" scale="0.001 0.001 0.001"/>
      </geometry>
      <material name="Black"/>
    </visual>
    <collision>
      <origin rpy="0 0 0" xyz="-0.01 0.0 -0.0225"/>
      <geometry>
        <box size="0.043 0.033 0.045"/>
      </geometry>
    </collision>
  </link>
  <joint name="right_arm_wrist_flex_joint" type="revolute">
    <origin rpy="-1.570795 1.570795 0" xyz="-0.012 0.0225 -0.097"/>
    <axis xyz="0 0 1"/>
    <limit effort="1.0" lower="-2.7" upper="2.7" velocity="1.571"/>
    <parent link="right_arm_forearm_flex_link"/>
    <child link="right_arm_wrist_flex_link"/>
  </joint>
  <link name="right_arm_wrist_flex_link">
    <inertial>
      <mass value="0.00001"/>
      <origin xyz="0 0 0"/>
      <inertia ixx="1.0" ixy="0.0" ixz="0.0" iyy="1.0" iyz="0.0" izz="1.0"/>
    </inertial>
    <visual>
      <origin rpy="0 0 0" xyz="0 0 0"/>
      <geometry>
        <mesh filename="package://akira_description/meshes/RS405CB.stl" scale="0.001 0.001 0.001"/>
      </geometry>
      <material name="Black"/>
    </visual>
    <collision>
      <origin rpy="0 0 0" xyz="-0.01 0.0 -0.0225"/>
      <geometry>
        <box size="0.043 0.033 0.045"/>
      </geometry>
    </collision>
  </link>
  <!-- Attach the right gripper -->
  <joint name="right_gripper_base_joint" type="revolute">
    <origin rpy="1.570795 -1.570795 0" xyz="0.0805 -0.023 -0.012"/>
    <axis xyz="0 0 1"/>
    <limit effort="1.0" lower="-3.14" upper="3.14" velocity="1.571"/>
    <parent link="right_arm_wrist_flex_link"/>
    <child link="right_gripper_base_link"/>
  </joint>
  <link name="right_gripper_base_link">
    <inertial>
      <mass value="0.00001"/>
      <origin xyz="0 0 0"/>
      <inertia ixx="1.0" ixy="0.0" ixz="0.0" iyy="1.0" iyz="0.0" izz="1.0"/>
    </inertial>
    <visual>
      <origin rpy="0 0 0" xyz="0 0 0"/>
      <geometry>
        <mesh filename="package://akira_description/meshes/RS405CB.stl" scale="0.001 0.001 0.001"/>
      </geometry>
      <material name="Black"/>
    </visual>
    <collision>
      <origin rpy="0 0 0" xyz="-0.01 0.0 -0.0225"/>
      <geometry>
        <box size="0.043 0.033 0.045"/>
      </geometry>
    </collision>
  </link>
  <joint name="right_gripper_joint" type="fixed">
    <axis xyz="0 0 1"/>
    <origin rpy="1.570795 0 0" xyz="0.04 -0.045 -0.0225"/>
    <parent link="right_gripper_base_link"/>
    <child link="right_gripper_link"/>
  </joint>
  <link name="right_gripper_link">
    <visual>
      <origin rpy="0 0 0" xyz="0 0 0"/>
      <geometry>
        <box size="0.001 0.0005 0.0005"/>
      </geometry>
    </visual>
  </link>
</robot>
