<?xml version="1.0" ?>
<!-- =================================================================================== -->
<!-- |    This document was autogenerated by xacro from /home/robot/akira-ros/src/akiracontrol/akira_description/urdf/akira.xacro | -->
<!-- |    EDITING THIS FILE BY HAND IS NOT RECOMMENDED                                 | -->
<!-- =================================================================================== -->
<robot name="akira" xmlns:xacro="http://ros.org/wiki/xacro">
  <!-- Define a number of dimensions using properties -->
  <!-- face_offset_z= ${torso_size_z}/2 + ${face_size_z}/2 -->
  <!-- Include all component files -->
  <material name="Black">
    <color rgba="0.2 0.2 0.2 1.0"/>
  </material>
  <material name="TransparentBlack">
    <color rgba="0.2 0.2 0.2 0.8"/>
  </material>
  <material name="Orange">
    <color rgba="1.0 0.55 0.0 1.0"/>
  </material>
  <material name="Grey">
    <color rgba="0.7 0.7 0.7 1.0"/>
  </material>
  <material name="DarkGrey">
    <color rgba="0.3 0.3 0.3 1.0"/>
  </material>
  <material name="Red">
    <color rgba="0.8 0.0 0.0 1.0"/>
  </material>
  <material name="White">
    <color rgba="1.0 1.0 1.0 1.0"/>
  </material>
  <material name="OffWhite">
    <color rgba="0.8 0.8 0.8 1.0"/>
  </material>
  <material name="Blue">
    <color rgba="0.0 0.0 0.8 1.0"/>
  </material>
  <material name="Green">
    <color rgba="0.0 0.8 0.0 1.0"/>
  </material>
  <material name="TransparentGreen">
    <color rgba="0.0 0.8 0.0 0.5"/>
  </material>
  <material name="Danboru">
    <!--color rgba="0.796 0.663 0.090 1.0"/-->
    <color rgba="0.784 0.627 0.392 1.0"/>
  </material>
  <link name="base_footprint">
    <visual>
      <origin rpy="0 0 0" xyz="0 0 0"/>
      <geometry>
        <box size="0.05 0.05 0.001"/>
      </geometry>
      <material name="TransparentGreen"/>
    </visual>
  </link>
  <joint name="base_joint" type="fixed">
    <origin rpy="0 0 0" xyz="0 0 -0.15"/>
    <parent link="base_link"/>
    <child link="base_footprint"/>
  </joint>
  <!-- Add the base and wheels -->
  <link name="base_link">
    <visual>
      <origin rpy="0 0 0" xyz="0 0 0"/>
      <geometry>
        <!--mesh filename="package://akira_description/meshes/akira_vehicle.stl" scale="${base_mesh_scale} ${base_mesh_scale} ${base_mesh_scale}" /-->
        <cylinder length="0.3" radius="0.25"/>
      </geometry>
      <material name="Black"/>
    </visual>
    <collision>
      <origin rpy="0 0 0" xyz="0 0 0"/>
      <geometry>
        <cylinder length="0.3" radius="0.3"/>
      </geometry>
    </collision>
  </link>
  <!-- Attach the torso -->
  <joint name="base_torso_joint" type="fixed">
    <origin rpy="0 0 0" xyz="0.0 0.0 0.55"/>
    <parent link="base_link"/>
    <child link="torso_link"/>
  </joint>
  <link name="torso_link">
    <visual>
      <origin rpy="0 0 0" xyz="0 0 0"/>
      <geometry>
        <!--mesh filename="package://akira_description/meshes/akira_torso.stl" scale="${TORSO_MESH_SCALE} ${TORSO_MESH_SCALE} ${TORSO_MESH_SCALE}" /-->
        <box size="0.29 0.46 0.77"/>
      </geometry>
      <material name="Danboru"/>
    </visual>
    <collision>
      <origin rpy="0 0 0" xyz="0 0 0"/>
      <geometry>
        <!--box size="${torso_size_x} ${torso_size_y} ${torso_size_z}" /-->
        <!-- !!! 2014.12.15 modified for debug !!! -->
        <box size="0.2 0.2 0.2"/>
      </geometry>
    </collision>
  </link>
  <!-- Attach the right arm -->
  <link name="right_arm_base_link"/>
  <joint name="right_arm_base_joint" type="fixed">
    <origin rpy="0 0 0" xyz="0.1 -0.2 0.2"/>
    <parent link="torso_link"/>
    <child link="right_arm_base_link"/>
  </joint>
  <joint name="right_arm_shoulder_lift_R_joint" type="revolute">
    <origin rpy="-1.57075 1.57075 0" xyz="0 0 0"/>
    <axis xyz="0 0 1"/>
    <limit effort="1.0" lower="-0.76" upper="1.75" velocity="1.571"/>
    <parent link="right_arm_base_link"/>
    <child link="right_arm_shoulder_lift_R_link"/>
  </joint>
  <link name="right_arm_shoulder_lift_R_link">
    <inertial>
      <mass value="0.00001"/>
      <origin xyz="0 0 0"/>
      <inertia ixx="1.0" ixy="0.0" ixz="0.0" iyy="1.0" iyz="0.0" izz="1.0"/>
    </inertial>
    <visual>
      <origin rpy="0 0 0" xyz="0 0 0"/>
      <geometry>
        <mesh filename="package://akira_description/meshes/RS405CB.stl" scale="0.001 0.001 0.001"/>
        <!--box size="${RS405CB_HEIGHT} ${RS405CB_WIDTH} ${RS405CB_DEPTH}"/-->
      </geometry>
      <material name="Black"/>
    </visual>
    <collision>
      <origin rpy="0 0 0" xyz="-0.01 0.0 -0.0225"/>
      <geometry>
        <!--box size="${RS405CB_HEIGHT} ${RS405CB_WIDTH} ${RS405CB_DEPTH}"/-->
        <box size="0.001 0.001 0.001"/>
      </geometry>
    </collision>
  </link>
  <joint name="right_arm_shoulder_lift_L_joint" type="revolute">
    <origin rpy="1.57075 1.57075 0" xyz="0 -0.09 0"/>
    <axis xyz="0 0 1"/>
    <limit effort="1.0" lower="-0.76" upper="1.75" velocity="1.571"/>
    <parent link="right_arm_base_link"/>
    <child link="right_arm_shoulder_lift_L_link"/>
  </joint>
  <link name="right_arm_shoulder_lift_L_link">
    <inertial>
      <mass value="0.00001"/>
      <origin xyz="0 0 0"/>
      <inertia ixx="1.0" ixy="0.0" ixz="0.0" iyy="1.0" iyz="0.0" izz="1.0"/>
    </inertial>
    <visual>
      <origin rpy="0 0 0" xyz="0 0 0"/>
      <geometry>
        <mesh filename="package://akira_description/meshes/RS405CB.stl" scale="0.001 0.001 0.001"/>
        <!--box size="${RS405CB_HEIGHT} ${RS405CB_WIDTH} ${RS405CB_DEPTH}"/-->
      </geometry>
      <material name="Black"/>
    </visual>
    <collision>
      <origin rpy="0 0 0" xyz="-0.01 0.0 -0.0225"/>
      <geometry>
        <!--box size="${RS405CB_HEIGHT} ${RS405CB_WIDTH} ${RS405CB_DEPTH}"/-->
        <box size="0.001 0.001 0.001"/>
      </geometry>
    </collision>
  </link>
  <joint name="right_arm_shoulder_roll_joint" type="revolute">
    <origin rpy="1.57075 0 3.1415" xyz="0 0.0215 0.06"/>
    <axis xyz="0 0 1"/>
    <limit effort="1.0" lower="-1.75" upper="0" velocity="1.571"/>
    <parent link="right_arm_shoulder_lift_L_link"/>
    <child link="right_arm_shoulder_roll_link"/>
  </joint>
  <link name="right_arm_shoulder_roll_link">
    <inertial>
      <mass value="0.00001"/>
      <origin xyz="0 0 0"/>
      <inertia ixx="1.0" ixy="0.0" ixz="0.0" iyy="1.0" iyz="0.0" izz="1.0"/>
    </inertial>
    <visual>
      <origin rpy="0 0 0" xyz="0 0 0"/>
      <geometry>
        <mesh filename="package://akira_description/meshes/RS405CB.stl" scale="0.001 0.001 0.001"/>
        <!--box size="${RS405CB_HEIGHT} ${RS405CB_WIDTH} ${RS405CB_DEPTH}"/-->
      </geometry>
      <material name="Black"/>
    </visual>
    <collision>
      <origin rpy="0 0 0" xyz="-0.01 0.0 -0.0225"/>
      <geometry>
        <!--box size="${RS405CB_HEIGHT} ${RS405CB_WIDTH} ${RS405CB_DEPTH}"/-->
        <box size="0.001 0.001 0.001"/>
      </geometry>
    </collision>
  </link>
  <joint name="right_arm_shoulder_pan_joint" type="revolute">
    <origin rpy="3.1415 -1.57075 0" xyz="-0.052 0 -0.0215"/>
    <axis xyz="0 0 1"/>
    <limit effort="1.0" lower="-1.57" upper="1.57" velocity="3.14"/>
    <parent link="right_arm_shoulder_roll_link"/>
    <child link="right_arm_shoulder_pan_link"/>
  </joint>
  <link name="right_arm_shoulder_pan_link">
    <inertial>
      <mass value="0.00001"/>
      <origin xyz="0 0 0"/>
      <inertia ixx="1.0" ixy="0.0" ixz="0.0" iyy="1.0" iyz="0.0" izz="1.0"/>
    </inertial>
    <visual>
      <origin rpy="0 0 0" xyz="0 0 0"/>
      <geometry>
        <mesh filename="package://akira_description/meshes/RS405CB.stl" scale="0.001 0.001 0.001"/>
        <!--box size="${RS405CB_HEIGHT} ${RS405CB_WIDTH} ${RS405CB_DEPTH}"/-->
      </geometry>
      <material name="Black"/>
    </visual>
    <collision>
      <origin rpy="0 0 0" xyz="-0.01 0.0 -0.0225"/>
      <geometry>
        <!--box size="${RS405CB_HEIGHT} ${RS405CB_WIDTH} ${RS405CB_DEPTH}"/-->
        <box size="0.001 0.001 0.001"/>
      </geometry>
    </collision>
  </link>
  <joint name="right_arm_elbow_flex_joint" type="revolute">
    <origin rpy="-1.57075 0 0" xyz="0 0.0225 -0.0865"/>
    <axis xyz="0 0 1"/>
    <limit effort="1.0" lower="-1.57" upper="0" velocity="3.14"/>
    <parent link="right_arm_shoulder_pan_link"/>
    <child link="right_arm_elbow_flex_link"/>
  </joint>
  <link name="right_arm_elbow_flex_link">
    <inertial>
      <mass value="0.00001"/>
      <origin xyz="0 0 0"/>
      <inertia ixx="1.0" ixy="0.0" ixz="0.0" iyy="1.0" iyz="0.0" izz="1.0"/>
    </inertial>
    <visual>
      <origin rpy="0 0 0" xyz="0 0 0"/>
      <geometry>
        <mesh filename="package://akira_description/meshes/RS405CB.stl" scale="0.001 0.001 0.001"/>
        <!--box size="${RS405CB_HEIGHT} ${RS405CB_WIDTH} ${RS405CB_DEPTH}"/-->
      </geometry>
      <material name="Black"/>
    </visual>
    <collision>
      <origin rpy="0 0 0" xyz="-0.01 0.0 -0.0225"/>
      <geometry>
        <!--box size="${RS405CB_HEIGHT} ${RS405CB_WIDTH} ${RS405CB_DEPTH}"/-->
        <box size="0.001 0.001 0.001"/>
      </geometry>
    </collision>
  </link>
  <joint name="right_arm_forearm_flex_joint" type="revolute">
    <origin rpy="1.57075 0 0" xyz="0 0.032 -0.0225"/>
    <axis xyz="0 0 1"/>
    <limit effort="1.0" lower="-1.57" upper="1.57" velocity="3.14"/>
    <parent link="right_arm_elbow_flex_link"/>
    <child link="right_arm_forearm_flex_link"/>
  </joint>
  <link name="right_arm_forearm_flex_link">
    <inertial>
      <mass value="0.00001"/>
      <origin xyz="0 0 0"/>
      <inertia ixx="1.0" ixy="0.0" ixz="0.0" iyy="1.0" iyz="0.0" izz="1.0"/>
    </inertial>
    <visual>
      <origin rpy="0 0 0" xyz="0 0 0"/>
      <geometry>
        <mesh filename="package://akira_description/meshes/RS405CB.stl" scale="0.001 0.001 0.001"/>
        <!--box size="${RS405CB_HEIGHT} ${RS405CB_WIDTH} ${RS405CB_DEPTH}"/-->
      </geometry>
      <material name="Black"/>
    </visual>
    <collision>
      <origin rpy="0 0 0" xyz="-0.01 0.0 -0.0225"/>
      <geometry>
        <!--box size="${RS405CB_HEIGHT} ${RS405CB_WIDTH} ${RS405CB_DEPTH}"/-->
        <box size="0.001 0.001 0.001"/>
      </geometry>
    </collision>
  </link>
  <joint name="right_arm_wrist_flex_joint" type="revolute">
    <origin rpy="-1.57075 1.57075 0" xyz="-0.012 0.0225 -0.097"/>
    <axis xyz="0 0 1"/>
    <limit effort="1.0" lower="-1.57" upper="1.57" velocity="3.14"/>
    <parent link="right_arm_forearm_flex_link"/>
    <child link="right_arm_wrist_flex_link"/>
  </joint>
  <link name="right_arm_wrist_flex_link">
    <inertial>
      <mass value="0.00001"/>
      <origin xyz="0 0 0"/>
      <inertia ixx="1.0" ixy="0.0" ixz="0.0" iyy="1.0" iyz="0.0" izz="1.0"/>
    </inertial>
    <visual>
      <origin rpy="0 0 0" xyz="0 0 0"/>
      <geometry>
        <mesh filename="package://akira_description/meshes/RS405CB.stl" scale="0.001 0.001 0.001"/>
        <!--box size="${RS405CB_HEIGHT} ${RS405CB_WIDTH} ${RS405CB_DEPTH}"/-->
      </geometry>
      <material name="Black"/>
    </visual>
    <collision>
      <origin rpy="0 0 0" xyz="-0.01 0.0 -0.0225"/>
      <geometry>
        <!--box size="${RS405CB_HEIGHT} ${RS405CB_WIDTH} ${RS405CB_DEPTH}"/-->
        <box size="0.001 0.001 0.001"/>
      </geometry>
    </collision>
  </link>
  <!-- Attach the right gripper -->
  <joint name="right_gripper_joint" type="fixed">
    <origin rpy="1.57075 0 0" xyz="0.13 0 0"/>
    <axis xyz="0 0 1"/>
    <parent link="right_arm_wrist_flex_link"/>
    <child link="right_gripper_link"/>
  </joint>
  <link name="right_gripper_link">
    <visual>
      <origin rpy="0 0 0" xyz="0 0 0"/>
      <geometry>
        <box size="0.001 0.0005 0.0005"/>
      </geometry>
    </visual>
    <collision>
      <origin rpy="0 0 0" xyz="-0.05 0 0"/>
      <geometry>
        <box size="0.001 0.001 0.001"/>
      </geometry>
    </collision>
  </link>
  <!-- Attach the face -->
  <joint name="torso_face_joint" type="fixed">
    <origin rpy="0 0 0" xyz="-0.03 0.0 0.532"/>
    <parent link="torso_link"/>
    <child link="face_link"/>
  </joint>
  <link name="face_link">
    <visual>
      <origin rpy="0 0 0" xyz="0 0 0"/>
      <geometry>
        <!--mesh filename="package://akira_description/meshes/akira_face.stl" scale="${FACE_MESH_SCALE} ${FACE_MESH_SCALE} ${FACE_MESH_SCALE}" /-->
        <box size="0.3 0.438 0.294"/>
      </geometry>
      <material name="Danboru"/>
    </visual>
    <collision>
      <origin rpy="0 0 0" xyz="0 0 0"/>
      <geometry>
        <box size="0.3 0.438 0.294"/>
      </geometry>
    </collision>
  </link>
  <!-- Attach the camera -->
  <joint name="torso_camera_joint" type="fixed">
    <origin rpy="0 0 0" xyz="0.1 0.0 0.695"/>
    <parent link="torso_link"/>
    <child link="camera_link"/>
  </joint>
  <link name="camera_link">
    <visual>
      <origin rpy="0 0 1.57075" xyz="0 0 0"/>
      <geometry>
        <mesh filename="package://akira_description/meshes/kinect.dae" scale="1.0 1.0 1.0"/>
      </geometry>
      <material name="Black"/>
    </visual>
    <collision>
      <origin rpy="0 0 0" xyz="0 0 0"/>
      <geometry>
        <box size="0.07271 0.27794 0.07"/>
      </geometry>
    </collision>
  </link>
  <joint name="camera_depth_joint" type="fixed">
    <origin rpy="0 0 0" xyz="0 0.0125 0.015"/>
    <parent link="camera_link"/>
    <child link="camera_depth_frame"/>
  </joint>
  <link name="camera_depth_frame">
    <inertial>
      <mass value="0.000001"/>
      <origin xyz="0 0 0"/>
      <inertia ixx="0.0001" ixy="0.0" ixz="0.0" iyy="0.0001" iyz="0.0" izz="0.0001"/>
    </inertial>
  </link>
  <joint name="camera_depth_optical_joint" type="fixed">
    <origin rpy="-1.57075 0 -1.57075" xyz="0 0 0"/>
    <parent link="camera_depth_frame"/>
    <child link="camera_depth_optical_frame"/>
  </joint>
  <link name="camera_depth_optical_frame">
    <inertial>
      <mass value="0.000001"/>
      <origin xyz="0 0 0"/>
      <inertia ixx="0.0001" ixy="0.0" ixz="0.0" iyy="0.0001" iyz="0.0" izz="0.0001"/>
    </inertial>
  </link>
  <joint name="camera_rgb_joint" type="fixed">
    <origin rpy="0 0 0" xyz="0 -0.0125 0.015"/>
    <parent link="camera_link"/>
    <child link="camera_rgb_frame"/>
  </joint>
  <link name="camera_rgb_frame">
    <inertial>
      <mass value="0.000001"/>
      <origin xyz="0 0 0"/>
      <inertia ixx="0.0001" ixy="0.0" ixz="0.0" iyy="0.0001" iyz="0.0" izz="0.0001"/>
    </inertial>
  </link>
  <joint name="camera_rgb_optical_joint" type="fixed">
    <origin rpy="-1.57075 0 -1.57075" xyz="0 0 0"/>
    <parent link="camera_rgb_frame"/>
    <child link="camera_rgb_optical_frame"/>
  </joint>
  <link name="camera_rgb_optical_frame">
    <inertial>
      <mass value="0.000001"/>
      <origin xyz="0 0 0"/>
      <inertia ixx="0.0001" ixy="0.0" ixz="0.0" iyy="0.0001" iyz="0.0" izz="0.0001"/>
    </inertial>
  </link>
  <!-- Attach the laser -->
  <joint name="base_laser_bottom_joint" type="fixed">
    <origin rpy="0 0 0 " xyz="0.19 0.0 0.16"/>
    <parent link="base_link"/>
    <child link="base_laser_bottom"/>
  </joint>
  <link name="base_laser_bottom">
    <visual>
      <origin rpy="0 0 0" xyz="0 0 0"/>
      <geometry>
        <box size="0.05 0.05 0.041"/>
      </geometry>
      <material name="DarkGrey"/>
    </visual>
    <collision>
      <origin rpy="0 0 0" xyz="0 0 0"/>
      <geometry>
        <box size="0.05 0.05 0.041"/>
      </geometry>
    </collision>
    <inertial>
      <mass value="0.1"/>
      <inertia ixx="0.001" ixy="0.0" ixz="0.0" iyy="0.001" iyz="0.0" izz="0.001"/>
    </inertial>
  </link>
  <link name="base_laser_middle">
    <visual>
      <origin rpy="0 0 0" xyz="0 0 0"/>
      <geometry>
        <cylinder length="0.0115" radius=".02"/>
      </geometry>
      <material name="dark_grey">
        <color rgba="0.2 0.2 0.2 1.0"/>
      </material>
    </visual>
    <collision>
      <origin rpy="0 0 0" xyz="0 0 0"/>
      <geometry>
        <cylinder length="0.0115" radius=".02"/>
      </geometry>
    </collision>
    <inertial>
      <mass value="0.1"/>
      <inertia ixx="0.001" ixy="0.0" ixz="0.0" iyy="0.001" iyz="0.0" izz="0.001"/>
    </inertial>
  </link>
  <joint name="base_laser_middle_joint" type="fixed">
    <parent link="base_laser_bottom"/>
    <child link="base_laser_middle"/>
    <origin rpy="0 0 0" xyz="0 0 0.02625"/>
  </joint>
  <link name="base_laser">
    <visual>
      <origin rpy="0 0 0" xyz="0 0 0"/>
      <geometry>
        <cylinder length="0.0175" radius=".0185"/>
      </geometry>
      <material name="red">
        <color rgba="0.8 0.1 0.1 1.0"/>
      </material>
    </visual>
    <collision>
      <origin rpy="0 0 0" xyz="0 0 0"/>
      <geometry>
        <cylinder length="0.0175" radius=".0185"/>
      </geometry>
    </collision>
    <inertial>
      <mass value="0.1"/>
      <inertia ixx="0.001" ixy="0.0" ixz="0.0" iyy="0.001" iyz="0.0" izz="0.001"/>
    </inertial>
  </link>
  <joint name="base_laser_joint" type="fixed">
    <parent link="base_laser_middle"/>
    <child link="base_laser"/>
    <origin rpy="0 0 0" xyz="0 0 0.0145"/>
  </joint>
</robot>
